Workbook
Name RadtoRPM: Parameter!$C$3
Name RPMtoRad: Parameter!$C$2
Name 磁链观测器锁相环带宽: Parameter!$C$52
Name 电机定子D轴电感: Input!$C$17
Name 电机定子Q轴电感: Input!$C$18
Name 电机定子相电阻: Input!$C$23
Name 电机额定电压: Input!$C$2
Name 电机反电势系数: Input!$C$10
Name 电机转动惯量: Input!$C$12
Name 电机转子磁链: Input!$C$11
Name 电机转子极对数: Input!$C$16
Name 电流环带宽: Parameter!$C$16
Name 仿真基础步长: Simulink!$C$2
Name 高频任务步长: Simulink!$C$3
Name 滑膜观测器锁相环带宽: Parameter!$C$49
Name 龙贝格观测器锁相环带宽: Parameter!$C$55
Name 死区时间: Input!$C$27
Name 中频任务步长: Simulink!$C$4
Name 转速环Ki: Parameter!$C$15
Name 转速环Kp: Parameter!$C$10
Name 转速环带宽: Parameter!$C$7

Sheet Input
A1: SignalName | B1: DataType | C1: DataValue | D1: DataValueMin | E1: DataValueMax | F1: StorageClass | G1: CustomStorageClass | H1: Description | I1: Unit
A2: MC_Input_Vdc | B2: double | C2: 13.5 | D2: 0 | E2: 500 | F2: Const | G2: 1 | H2: 电机额定电压 | I2: V
A3: MC_Input_VdcMax | B3: double | C3: 16 | D3: 0 | E3: 500 | F3: Const | G3: 1 | H3: 电机最大工作电压 | I3: V
A4: MC_Input_VdcMin | B4: double | C4: 8 | D4: 0 | E4: 500 | F4: Const | G4: 1 | H4: 电机最小工作电压 | I4: V
A5: MC_Input_Ibus | B5: double | C5: 80 | D5: 0 | E5: 500 | F5: Const | G5: 1 | H5: 电机最大电流 | I5: A
A6: MC_Input_Power | B6: double | C6: 4 | D6: 0 | E6: 500 | F6: Const | G6: 1 | H6: 电机最大功率 | I6: W
A7: MC_Motor_ModelType | B7: single | C7: 1 | D7: 0 | E7: 500 | F7: Const | G7: 1 | H7: 电机模型
A8: MC_Motor_WindType | B8: single | C8: 1 | D8: 0 | E8: 500 | F8: Const | G8: 1 | H8: 电机定子绕组模型
A9: MC_Motor_SpeedMax | B9: double | C9: 3000 | D9: 0 | E9: 500 | F9: Const | G9: 1 | H9: 电机最大转速 | I9: RPM
A10: MC_Motor_BEMF | B10: double | C10: 4.294 | D10: 0 | E10: 500 | F10: Const | G10: 1 | H10: 电机反电势系数 | I10: V/krpm
A11: MC_Motor_Phi | B11: double | C11: =(电机反电势系数*60/(1000*2*PI()*电机转子极对数))*0.5774 -> 0.0059190255 | D11: 0 | E11: 500 | F11: Const | G11: 1 | H11: 电机永磁体磁链 | I11: Wb
A12: MC_Motor_Mechinal_Inertia | B12: double | C12: 0.0103 | D12: 0 | E12: 500 | F12: Const | G12: 1 | H12: 电机转动惯量 | I12: kg*m^2
A13: MC_Motor_Mechinal_Damp | B13: double | C13: 1e-05 | D13: 0 | E13: 500 | F13: Const | G13: 1 | H13: 电机机械阻尼 | I13: N*m*s/rad
A14: MC_Motor_Mechinal_Fric | B14: double | C14: 0 | D14: 0 | E14: 500 | F14: Const | G14: 1 | H14: 电机静摩擦
A15: MC_Motor_Mechinal_TF | B15: double | C15: 0.0859 | D15: 0 | E15: 500 | F15: Const | G15: 1 | H15: 电机阻力系数
A16: MC_Motor_Rotor_Pn | B16: double | C16: 4 | D16: 0 | E16: 500 | F16: Const | G16: 1 | H16: 电机转子极对数
A17: MC_Motor_Stator_Ld | B17: double | C17: 5.6345e-05 | D17: 0 | E17: 500 | F17: Const | G17: 1 | H17: 电机定子D轴电感 | I17: H
A18: MC_Motor_Stator_Lq | B18: double | C18: 5.6345e-05 | D18: 0 | E18: 500 | F18: Const | G18: 1 | H18: 电机定子Q轴电感 | I18: H
A19: MC_Motor_Stator_L0 | B19: double | C19: 0 | D19: 0 | E19: 500 | F19: Const | G19: 1 | H19: 电机定子零序电感 | I19: H
A20: MC_Motor_Stator_Lalpha | B20: double | C20: =(电机定子D轴电感+电机定子Q轴电感)/2 -> 5.6345e-05 | D20: 0 | E20: 500 | F20: Const | G20: 1 | H20: 电机定子零序电感 | I20: H
A21: MC_Motor_Stator_Lbeta | B21: double | C21: =(电机定子D轴电感+电机定子Q轴电感)/2 -> 5.6345e-05 | D21: 0 | E21: 500 | F21: Const | G21: 1 | H21: 电机定子零序电感 | I21: H | L21: =电机定子相电阻/C21 -> 507.58719
A22: MC_Motor_Stator_Lalphabeta | B22: double | C22: =(电机定子Q轴电感-电机定子D轴电感)/2 -> 0 | D22: 0 | E22: 500 | F22: Const | G22: 1 | H22: 电机定子零序电感 | I22: H
A23: MC_Motor_Stator_Rs | B23: double | C23: 0.0286 | D23: 0 | E23: 500 | F23: Const | G23: 1 | H23: 电机定子相电阻 | I23: Ω、Ohm
A24: MC_MOS_Rds | B24: double | C24: 0.001 | D24: 0 | E24: 500 | F24: Const | G24: 1 | H24: 逆变器MOS管内阻 | I24: Ω、Ohm
A25: MC_MOS_Threshold | B25: double | C25: 0.5 | D25: 0 | E25: 500 | F25: Const | G25: 1 | H25: 逆变器MOS管开启电压 | I25: V
A26: MC_MOS_Cs | B26: double | C26: 1e-06 | D26: 0 | E26: 500 | F26: Const | G26: 1 | H26: 逆变器MOS管参数 | I26: Ohm
A27: MC_MOS_DeadTime | B27: single | C27: 1.3e-06 | D27: 0 | E27: 1 | F27: Const | G27: 1 | H27: 逆变器上下桥死区时间 | I27: s
A28: MC_ADC_Ts | B28: single | C28: 6e-07 | D28: 0 | E28: 500 | F28: Const | G28: 1 | H28: ADC采样和转换时间 | I28: s
A29: MC_CSA_Gain | B29: double | C29: 1 | D29: 0 | E29: 500 | F29: Const | G29: 1 | H29: CSA放大增益
A30: MC_ADC_Offset | B30: double | C30: 0 | D30: 0 | E30: =C32 -> 1 | F30: Const | G30: 1 | H30: ADC采样偏执电压 | I30: V
A31: MC_ADC_BitNum | B31: double | C31: 0 | D31: 0 | E31: 24 | F31: Const | G31: 1 | H31: ADC采样位数
A32: MC_ADC_VRef | B32: double | C32: 1 | D32: 0 | E32: 5 | F32: Const | G32: 1 | H32: ADC采样参考电压 | I32: V
A33: MC_Sample_Model | B33: double | C33: 1 | D33: 0 | E33: 500 | F33: Const | G33: 1 | H33: 相电流采样策略 1：单电阻；2：双电阻；3：三电阻
A34: MC_Sample_ORSType | B34: double | C34: 2 | D34: 0 | E34: 500 | F34: Const | G34: 1 | H34: 单电阻采样策略 1：单边采样；2：双边采样
A35: MC_Sample_Rs | B35: double | C35: 0.002 | D35: 0 | E35: 500 | F35: Const | G35: 1 | H35: 硬件采样电阻 | I35: Ohm
A36: MC_Sample_ValidTime | B36: single | C36: =C28 -> 6e-07 | D36: 0 | E36: 1 | F36: Const | G36: 1 | H36: 电流采样最小有效时间 | I36: s
A37: MC_Sample_VbusNoise | B37: double | C37: 1e-15 | D37: 0 | E37: 500 | F37: Const | G37: 1 | H37: 母线电压采样噪声功率
A38: MC_Sample_CurrentNoise | B38: double | C38: 1e-15 | D38: 0 | E38: 500 | F38: Const | G38: 1 | H38: 相电流采样噪声功率

Sheet Simulink
A1: SignalName | B1: DataType | C1: DataValue | D1: DataValueMin | E1: DataValueMax | F1: StorageClass | G1: CustomStorageClass | H1: Description | I1: Unit
A2: MC_Sim_BaseStep | B2: double | C2: =ROUND(1/C5,10) -> 2.08e-08 | D2: 0 | E2: 1 | F2: Const | H2: 基础步长
A3: MC_Sim_HFTStep | B3: double | C3: =ROUND(C5/C6,0)*仿真基础步长 -> 6.24e-05 | D3: 0 | E3: 1 | F3: Const | H3: 高频任务步长
A4: MC_Sim_MFTStep | B4: double | C4: =ROUND(C6/C7,0)*高频任务步长 -> 0.0019968 | D4: 0 | E4: 1 | F4: Const | H4: 中频任务步长
A5: MC_Sim_BaseFreq | B5: double | C5: 48000000 | D5: 0 | E5: 1 | F5: Const | H5: 基础步长
A6: MC_Sim_HFTFreq | B6: double | C6: 16000 | D6: 0 | E6: 1 | F6: Const | H6: 高频任务步长
A7: MC_Sim_MFTFreq | B7: double | C7: 500 | D7: 0 | E7: 1 | F7: Const | H7: 中频任务步长

Sheet Parameter
A1: SignalName | B1: DataType | C1: DataValue | D1: DataValueMin | E1: DataValueMax | F1: StorageClass | G1: CustomStorageClass | H1: Description | I1: Unit
A2: MC_Param_RPMtoRad | B2: single | C2: =PI()/30 -> 0.10471976 | D2: 0 | E2: 500 | F2: Const | H2: RPM转换Rad | I2: 常数
A3: MC_Param_RadtoRPM | B3: single | C3: =30/PI() -> 9.5492966 | D3: 0 | E3: 500 | F3: Const | H3: Rad转换RPM
A4: MC_Param_SpeedtoTheta | B4: single | C4: =高频任务步长 -> 6.24e-05 | D4: 0 | E4: 500 | F4: Const | H4: 转速转换角度
A5: MC_Param_PhasetoReal | B5: single | C5: =Input!C32/(2^Input!C31*Input!C29*Input!C35) -> 500 | D5: 0 | E5: 100000000 | F5: Const | H5: 转速转换角度
A6: MC_Param_Zero | B6: single | C6: 0 | D6: 0 | E6: 0 | F6: Const | H6: 参数零值
A7: MC_Param_SpeedPI_Wc | B7: single | C7: 5 | D7: 0 | E7: 500 | F7: Const | H7: 转速环带宽 | I7: 转速环
A8: MC_Param_SpeedPI_Kp | B8: single | C8: =转速环带宽*2*PI()*电机转动惯量/(1.5*电机转子磁链*电机转子极对数) -> 9.111411 | D8: 0 | E8: 1000000000 | F8: Const | H8: 转速环Kp
A9: MC_Param_SpeedPI_Ki | B9: single | C9: =转速环Kp*转速环带宽*2*PI()*中频任务步长 -> 0.57157086 | D9: 0 | E9: 1000000000 | F9: Const | H9: 转速环Ki
A10: MC_Param_SpeedPI_Kp_II | B10: single | C10: =转速环带宽*2*PI()*电机转动惯量/(1.5*电机转子磁链*电机转子极对数) -> 9.111411 | D10: 0 | E10: 1000000000 | F10: Const | H10: 转速环Kp
A11: MC_Param_SpeedPI_Ki_II | B11: single | C11: =转速环Kp*转速环带宽*2*PI()*中频任务步长 -> 0.57157086 | D11: 0 | E11: 1000000000 | F11: Const | H11: 转速环Ki
A12: MC_Param_SpeedCtrl_IdMax | B12: single | C12: 60 | D12: =-E12 -> -80 | E12: =Input!C5 -> 80 | F12: Const | H12: 转速控制器Id最大输出
A13: MC_Param_SpeedCtrl_IdMin | B13: single | C13: -60 | D13: =-E13 -> -80 | E13: =Input!C5 -> 80 | F13: Const | H13: 转速环控制器Id最小输出
A14: MC_Param_SpeedCtrl_IqMax | B14: single | C14: 60 | D14: =-E14 -> -80 | E14: =Input!C5 -> 80 | F14: Const | H14: 转速控制器Iq最大输出
A15: MC_Param_SpeedCtrl_IqMin | B15: single | C15: -60 | D15: =-E15 -> -80 | E15: =Input!C5 -> 80 | F15: Const | H15: 转速环控制器Iq最小输出
A16: MC_Param_CurrentPI_Wc | B16: single | C16: 800 | D16: 0 | E16: 1000000000 | F16: Const | H16: 电流环带宽 | I16: 电流环
A17: MC_Param_CurrentPI_Kp | B17: single | C17: {=电流环带宽*2*PI()*电机定子Q轴电感} -> 0.28322086 | D17: 0 | E17: 1000000000 | F17: Const | H17: 电流环Kp
A18: MC_Param_CurrentPI_Ki | B18: single | C18: =电流环带宽*2*PI()*电机定子相电阻*高频任务步长 -> 0.0089705791 | D18: 0 | E18: 1000000000 | F18: Const | H18: 电流环Ki
A19: MC_Param_CurrentPI_Err | B19: single | C19: 1 | D19: 0 | E19: 500 | F19: Const | H19: 电流环积分分离误差阈值
A20: MC_Param_CurrentPI_UdInitial | B20: single | C20: 0 | D20: 0 | E20: 13.5 | F20: Const | H20: 电流环Ud积分初值
A21: MC_Param_CurrentPI_UdInteMax | B21: single | C21: =电机额定电压/SQRT(3) -> 7.7942286 | D21: 0 | E21: 13.5 | F21: Const | H21: 电流环Ud积分上限
A22: MC_Param_CurrentPI_UdInteMin | B22: single | C22: =-电机额定电压/SQRT(3) -> -7.7942286 | D22: -13.5 | E22: 13.5 | F22: Const | H22: 电流环Ud积分下限
A23: MC_Param_CurrentPI_UdMax | B23: single | C23: =电机额定电压/SQRT(3) -> 7.7942286 | D23: 0 | E23: 13.5 | F23: Const | H23: 电流环Ud输出上限
A24: MC_Param_CurrentPI_UdMin | B24: single | C24: =-电机额定电压/SQRT(3) -> -7.7942286 | D24: -13.5 | E24: 13.5 | F24: Const | H24: 电流环Ud输出下限
A25: MC_Param_CurrentPI_UqInitial | B25: single | C25: 0 | D25: 0 | E25: 13.5 | F25: Const | H25: 电流环Uq积分初值
A26: MC_Param_CurrentPI_UqInteMax | B26: single | C26: =电机额定电压/SQRT(3) -> 7.7942286 | D26: 0 | E26: 13.5 | F26: Const | H26: 电流环Uq积分上限
A27: MC_Param_CurrentPI_UqInteMin | B27: single | C27: =-电机额定电压/SQRT(3) -> -7.7942286 | D27: -13.5 | E27: 13.5 | F27: Const | H27: 电流环Uq积分下限
A28: MC_Param_CurrentPI_UqMax | B28: single | C28: =电机额定电压/SQRT(3) -> 7.7942286 | D28: 0 | E28: 13.5 | F28: Const | H28: 电流环Uq输出上限
A29: MC_Param_CurrentPI_UqMin | B29: single | C29: =-电机额定电压/SQRT(3) -> -7.7942286 | D29: -13.5 | E29: 13.5 | F29: Const | H29: 电流环Uq输出下限
A30: MC_Paran_CurrentADRC_LESO_W0 | B30: single | C30: =1*2*PI() -> 6.2831853 | D30: 0 | E30: =电流环带宽*2*PI() -> 5026.5482 | F30: Const | H30: 电流ADRC的LESO带宽
A31: MC_Paran_CurrentADRC_NLSEF_Wc | B31: single | C31: =1*2*PI() -> 6.2831853 | D31: 0 | E31: =电流环带宽*2*PI() -> 5026.5482 | F31: Const | H31: 电流ADRC的NLSEF带宽
A32: MC_Param_SMO_CoffA | B32: single | C32: =1 - (高频任务步长*电机定子相电阻/电机定子Q轴电感) -> 0.96832656 | D32: 0 | E32: 500 | F32: Const | H32: 滑膜电流参数 | I32: 滑膜观测器
A33: MC_Param_SMO_CoffB | B33: single | C33: =高频任务步长/电机定子Q轴电感 -> 1.107463 | D33: 0 | E33: 500 | F33: Const | H33: 滑膜电压参数
A34: MC_Param_SMO_E_Max | B34: single | C34: 2 | D34: 0 | E34: 500 | F34: Const | H34: 滑膜饱和函数最大值
A35: MC_Param_SMO_E_Min | B35: single | C35: -2 | D35: -500 | E35: 0 | F35: Const | H35: 滑膜饱和函数最小值
A36: MC_Param_Flux_Gamma | B36: single | C36: 750000 | D36: 0 | E36: 1e+36 | F36: Const | H36: 磁链观测器增益 | I36: 磁链观测器
A37: MC_Param_Flux_Ralpha | B37: single | C37: =电机定子相电阻 -> 0.0286 | D37: 0 | E37: 1 | F37: Const | H37: 磁链观测器α轴电阻
A38: MC_Param_Flux_Rbeta | B38: single | C38: =电机定子相电阻 -> 0.0286 | D38: 0 | E38: 1 | F38: Const | H38: 磁链观测器β轴电阻
A39: MC_Param_Flux_Lalpha | B39: single | C39: =Input!C20 -> 5.6345e-05 | D39: 0 | E39: 1 | F39: Const | H39: 磁链观测器α轴电感
A40: MC_Param_Flux_Lbeta | B40: single | C40: =Input!C21 -> 5.6345e-05 | D40: 0 | E40: 1 | F40: Const | H40: 磁链观测器β轴电感
...

Sheet CodeGenerate
A1: SignalName | B1: DataType | C1: Dimensions | D1: DataValue | E1: DataValueMin | F1: DataValueMax | G1: StorageClass | H1: CustomStorageClass | I1: HeaderFile | J1: Description
A2: MC_Input_Vdc | B2: double | C2: 1 | D2: 13.5 | E2: 0 | F2: 48 | G2: 1 | H2: 1 | I2: 1 | J2: 电机工作电压

Sheet 标幺化
A1: 标幺变量 | B1: 标幺基准值 | C1: 标幺值 | D1: 误差

Sheet 定点化

Sheet 数据转化对照
